<?xml version="1.0" encoding="UTF-8"?>
<testsuite name="TestCollector-20231031011321" tests="3" file=".py" time="0.062" timestamp="2023-10-31T01:13:21" failures="0" errors="1" skipped="0">
	<testcase classname="TestCollector" name="test_init" time="0.003" timestamp="2023-10-31T01:13:21" file="test_cloudservice_api.py" line="43">
		<system-out><![CDATA[{'metadata': {'cloud_service_group_map': {'Compute': ['ServerInstanceManager',
                                                      'AutoscalingManager'],
                                          'Content Delivery': ['CdnManager'],
                                          'Database': ['CloudDBManager'],
                                          'Management': ['MonitoringManager'],
                                          'Networking': ['VPCNetworkManager'],
                                          'Storage': ['ObjectStorageManager',
                                                      'ArchiveStorageManager']},
              'filter_format': [],
              'supported_features': ['garbage_collection'],
              'supported_resource_type': ['inventory.CloudService',
                                          'inventory.CloudServiceType',
                                          'inventory.Region',
                                          'inventory.ErrorResource'],
              'supported_schedules': ['hours']}}

]]></system-out>
	</testcase>
	<testcase classname="TestCollector" name="test_verify" time="0.043" timestamp="2023-10-31T01:13:21" file="test_cloudservice_api.py" line="47">
		<system-out><![CDATA[{}

]]></system-out>
	</testcase>
	<testcase classname="TestCollector" name="test_collect" time="0.016" timestamp="2023-10-31T01:13:21" file="test_cloudservice_api.py" line="53">
		<error type="ERROR_INTERNAL_API" message="
	error_code = ERROR_LOCATOR
	status_code = INTERNAL
	message =  'ArchiveStorageManager' load failed. (reason = module 'spaceone.inventory.manager' has no attribute 'ArchiveStorageManager')"><![CDATA[Traceback (most recent call last):
  File "C:\Users\e268\plugin-naver-cloud-service-inven-collector\venv\lib\site-packages\spaceone\core\pygrpc\client.py", line 184, in _generate_response
    for response in response_iterator:
  File "C:\Users\e268\plugin-naver-cloud-service-inven-collector\venv\lib\site-packages\grpc\_channel.py", line 541, in __next__
    return self._next()
  File "C:\Users\e268\plugin-naver-cloud-service-inven-collector\venv\lib\site-packages\grpc\_channel.py", line 967, in _next
    raise self
grpc._channel._MultiThreadedRendezvous: <_MultiThreadedRendezvous of RPC that terminated with:
	status = StatusCode.INTERNAL
	details = "ERROR_LOCATOR: 'ArchiveStorageManager' load failed. (reason = module 'spaceone.inventory.manager' has no attribute 'ArchiveStorageManager')"
	debug_error_string = "UNKNOWN:Error received from peer  {created_time:"2023-10-30T16:13:21.5967326+00:00", grpc_status:13, grpc_message:"ERROR_LOCATOR: \'ArchiveStorageManager\' load failed. (reason = module \'spaceone.inventory.manager\' has no attribute \'ArchiveStorageManager\')"}"
>

During handling of the above exception, another exception occurred:

Traceback (most recent call last):
  File "C:\Users\e268\plugin-naver-cloud-service-inven-collector\test\api\test_cloudservice_api.py", line 82, in test_collect
    for res in resource_stream:
  File "C:\Users\e268\plugin-naver-cloud-service-inven-collector\venv\lib\site-packages\spaceone\core\pygrpc\client.py", line 187, in _generate_response
    self._check_error(e)
  File "C:\Users\e268\plugin-naver-cloud-service-inven-collector\venv\lib\site-packages\spaceone\core\pygrpc\client.py", line 163, in _check_error
    raise e
spaceone.core.error.ERROR_INTERNAL_API: 
	error_code = ERROR_LOCATOR
	status_code = INTERNAL
	message =  'ArchiveStorageManager' load failed. (reason = module 'spaceone.inventory.manager' has no attribute 'ArchiveStorageManager')
]]></error>
		<system-out><![CDATA[<generator object _ClientInterceptor._generate_response at 0x00000000068BF660>
]]></system-out>
	</testcase>
</testsuite>
